input.txt
A,10000,B,2,89
A,100000,B,2,94
A,100001,B,2,95
A,100002,B,1,96
A,100003,S,3,95
A,100004,S,4,94
A,100005,S,2,89
A,100006,B,2,94
A,100007,B,2,94
X,100007,B,2,94
A,100008,B,0,0
A,100009,B,1,0
A,100010,T,1,1
T,100011,B,1,1
A,100012,B,2,96
